Workbook

Sheet Start Here
B1: Weekday Interview Scheduling System
B2: Goal: 80% of interview requests SCHEDULED (via Calendly) within 24 hours of arrival.
B4: WHO DOES WHAT
B5: Ram = Digital outreach for EVERY new request (WhatsApp + Email + nudges).
B6: Shyam = Phone calls, but ONLY for requests Ram could not schedule (auto-escalated).
B7: You (Team Lead / AM) = handle the rare cases both interns escalate.
B9: YOUR DAILY ROUTINE (do this top to bottom, every day)
B10: 1. Open your tab: Ram -> 'Ram - Digital ToDo'. Shyam -> 'Shyam - Call ToDo'.
B11: 2. Sort your tab by 'Hours Left' (smallest first). Smallest = most urgent.
B12: 3. Read the 'NEXT STEP' column. It tells you EXACTLY what to do for that row.
B13: 4. Do it, then fill the dropdown for that step. The row updates itself.
B14: 5. Repeat down the list until every row says DONE, ESCALATED, DECLINED or CLOSED.
... B24: Start Here | Assumptions & Approach | Playbook (SOP) | Ram - Digital ToDo | Shyam - Call ToDo | KPI Dashboard | INPUT (clean)

Sheet Assumptions & Approach
B1: Assumptions, Thought Process & Approach
B2: This documentation is part of the deliverable. It explains every assumption and why the system is built the way it is.
B4: 1. HOW I BROKE THE PROBLEM DOWN
B5: The job is not 'schedule interviews' - it is 'get the candidate to click the Calendly link before the 24h clock runs out'. So the problem splits into 4 units:
B6: a) Intake & clean: dedupe, pick the right round's link, fix phone/email.
B7: b) Prioritise: sort by time-left so we never breach the 24h SLA.
B8: c) Chase via cheapest channel first: digital (Ram) -> phone (Shyam) -> lead.
B9: d) Measure: track % scheduled within 24h so we know if we are winning.
B11: 2. KEY ASSUMPTIONS
B12: A1. Candidates already agreed to interview, so the only task is to make them click Calendly.
B13: A2. Candidates are India-based; phones default to +91 and 'working hours' are 9:00-21:00 IST.
B14: A3. Ram has bulk tooling (WhatsApp Business broadcast + mail-merge) so the initial blast to ~500 people is a batch action, not 500 manual messages.
... B48: EDGE-CASE PLAYBOOK
B49: Edge case | C49: What the intern does
B50: Candidate ignores email | C50: WhatsApp + email are sent together at T+0; nudge at T+2h; call at T+6h.
B51: Candidate has no WhatsApp | C51: Blast also goes by email + SMS; if no WhatsApp delivery, Shyam calls.
B52: Candidate never answers calls | C52: Call 1 + Call 2 in golden hours; leave SMS/voicemail; then escalate to lead.
B53: Candidate forgot after agreeing | C53: Nudge script reminds them they already agreed; offer to book on their behalf.
B54: Invalid / wrong phone number | C54: Mark 'Invalid number' -> goes straight to lead to get correct details from company.
B55: Wrong / bouncing email | C55: Mark 'Bad contact' on blast -> lead asks the company for correct contact.
B56: No Calendly slots / interviewer busy | C56: Note it; lead pings the company to open slots; SLA clock paused with a note.
B57: Candidate wants to reschedule | C57: Send link again; they self-serve; counts as scheduled once booked.
B58: Candidate not interested / dropped | C58: Mark 'Not interested/Declined' -> closed + removed from SLA denominator.
B59: Candidate says STOP / do not contact | C59: Stop all outreach immediately; mark Declined; note 'DND'; tell lead.
B60: Duplicate request for same person | C60: 'Dup?' column flags it; process only the first, ignore the rest.
... B62: Request arrives late at night | C62: Cadence respects 9-21 working hours; night touches roll to 9:00 next day, still < 24h.

Sheet Playbook (SOP)
B1: Playbook (Standard Operating Procedure)
B2: Copy-paste these. Replace [BRACKETS] with the values from the row you are working.
B3: MESSAGE SCRIPTS (Ram)
B4: M1 - Initial WhatsApp | C4: Hi [Candidate], this is [Your name] from Weekday. Your [Round] interview with [Company] is confirmed. Please pick a time here: [Calendly Link]. It takes 30 seconds. Kindly book within today. Reply here if you face any issue.
B5: M1 - Initial Email | C5: Subject: Action needed: book your [Company] [Round] interview Hi [Candidate], you are confirmed for the [Round] interview with [Company]. Please choose a slot here: [Calendly Link]. Booking today keeps your process on track. Reply if the link does not work.
B6: M2 - Nudge WhatsApp (T+2h) | C6: Hi [Candidate], gentle reminder to lock your [Company] interview slot: [Calendly Link]. Takes under a minute. Want me to suggest a time?
B7: M3 - SMS fallback | C7: Weekday: Please book your [Company] [Round] interview: [Calendly Link]. Reply CALL if you want us to book for you.
B8: CALL SCRIPTS (Shyam)
B9: C1 - Call 1 opener | C9: Hi [Candidate], calling from Weekday about your confirmed [Company] [Round] interview. I can text you the booking link now, or I can book a slot for you right now - I have [slot A], [slot B], [slot C]. Which works?
B10: C1 - If they pick a slot | C10: Book it on Calendly yourself on their behalf, confirm by WhatsApp, then mark 'Booked on their behalf'.
B11: C2 - Call 2 (final) | C11: Hi [Candidate], last reminder so you do not lose your [Company] slot. Shall I book [slot A] or [slot B] for you right now?
B12: VM - Voicemail / no answer | C12: Send M3 SMS immediately after a missed call, then try again in the next golden hour (12:00-14:00 or 18:00-20:00).
B13: DECISION TABLE - what each dropdown outcome means and what happens next
B14: Where | C14: You select | What it means / next action
B15: Ram S1 Blast | C15: Sent -> Blast delivered. Wait for T+2h check.
B16: Ram S1 Blast | C16: Bad contact -> Email bounced AND no WhatsApp. Row blocks -> lead gets correct contact.
B17: Ram S2 Check | C17: Scheduled -> Candidate booked. Row is DONE. Stop.
B18: Ram S2 Check | C18: Not yet -> Not booked. Send nudge M2 (S3).
B19: Ram S3 Nudge | C19: Nudged -> Reminder sent. Wait for T+4h final check.
B20: Ram S4 Final | C20: Scheduled -> Booked. Row is DONE.
B21: Ram S4 Final | C21: Escalate to call -> Auto-sends row to Shyam's call queue.
B22: Shyam Call 1 | C22: Scheduled on call -> They booked while on call. DONE.
B23: Shyam Call 1 | C23: Booked on their behalf -> You booked for them. DONE. Confirm by WhatsApp.
B24: Shyam Call 1 | C24: No answer -> Send SMS, retry in next golden hour -> Call 2.
B25: Shyam Call 1 | C25: Invalid number -> Wrong number -> escalate to lead for correct details.
... B30: Shyam Call 2 | C30: Escalate to AM -> Lead takes over the last-mile attempt.
B31: DEFINITIONS
B32: Golden hours | C32: Best call pickup times: 12:00-14:00 and 18:00-20:00.
B33: Book on their behalf | C33: With verbal consent, you open Calendly and pick the slot for the candidate.
B34: SLA | C34: Service Level Agreement = the 24h window from 'Added On' to schedule the interview.

Sheet Ram - Digital ToDo
A1: Req ID | B1: Added On | C1: SLA Deadline | D1: Hours Left | E1: NEXT STEP | F1: Do By | G1: Candidate | H1: Company | I1: Round | J1: Phone | K1: Email | L1: Calendly Link (this round) | M1: Dup? | N1: S1 Blast | O1: S2 Calendly Check | P1: S3 Nudge | Q1: S4 Final Check | R1: Ram Status | S1: Notes
A2: REQ-0001 | B2: 44867.452 | C2: =B2+1 | D2: =(C2-NOW())*24 | E2: =IF(N2="","STEP 1: Send WhatsApp + Email blast now (Playbook M1)",IF(N2="Bad contact","STOP: report bad contact to lead (Playbook)",IF(O2="Scheduled","DONE: scheduled via Calendly",IF(O2="","STEP 2: Check Calendly now",IF(P2="","STEP 3: Send WhatsApp nudge (Playbook M2)",IF(Q2="Scheduled","DONE: scheduled via Calendly",IF(Q2="Escalate to call","HANDED to Shyam (call queue)","STEP 4: Final Calendly check"))))))) | F2: =IF(N2="",B2,IF(O2="",B2+2/24,IF(AND(O2="Not yet",P2=""),B2+2/24,IF(Q2="",B2+4/24,"")))) | G2: Chetan | H2: FB | I2: Round2 | J2: +91 9920264452 | K2: chetan@weekday.works | L2: <calendly_link> | M2: Yes | R2: =IF(OR(O2="Scheduled",Q2="Scheduled"),"SCHEDULED",IF(Q2="Escalate to call","ESCALATED TO CALL",IF(N2="Bad contact","BAD CONTACT",IF(N2="","NOT STARTED","IN PROGRESS"))))
A3: REQ-0002 | B3: 44867.494 | C3: =B3+1 | D3: =(C3-NOW())*24 | E3: =IF(N3="","STEP 1: Send WhatsApp + Email blast now (Playbook M1)",IF(N3="Bad contact","STOP: report bad contact to lead (Playbook)",IF(O3="Scheduled","DONE: scheduled via Calendly",IF(O3="","STEP 2: Check Calendly now",IF(P3="","STEP 3: Send WhatsApp nudge (Playbook M2)",IF(Q3="Scheduled","DONE: scheduled via Calendly",IF(Q3="Escalate to call","HANDED to Shyam (call queue)","STEP 4: Final Calendly check"))))))) | F3: =IF(N3="",B3,IF(O3="",B3+2/24,IF(AND(O3="Not yet",P3=""),B3+2/24,IF(Q3="",B3+4/24,"")))) | G3: Chetan | H3: Tesla | I3: Round3 | J3: +91 9920264452 | K3: chetan@weekday.works | L3: <calendly_link> | R3: =IF(OR(O3="Scheduled",Q3="Scheduled"),"SCHEDULED",IF(Q3="Escalate to call","ESCALATED TO CALL",IF(N3="Bad contact","BAD CONTACT",IF(N3="","NOT STARTED","IN PROGRESS"))))
A4: REQ-0003 | B4: 44867.619 | C4: =B4+1 | D4: =(C4-NOW())*24 | E4: =IF(N4="","STEP 1: Send WhatsApp + Email blast now (Playbook M1)",IF(N4="Bad contact","STOP: report bad contact to lead (Playbook)",IF(O4="Scheduled","DONE: scheduled via Calendly",IF(O4="","STEP 2: Check Calendly now",IF(P4="","STEP 3: Send WhatsApp nudge (Playbook M2)",IF(Q4="Scheduled","DONE: scheduled via Calendly",IF(Q4="Escalate to call","HANDED to Shyam (call queue)","STEP 4: Final Calendly check"))))))) | F4: =IF(N4="",B4,IF(O4="",B4+2/24,IF(AND(O4="Not yet",P4=""),B4+2/24,IF(Q4="",B4+4/24,"")))) | G4: Chetan | H4: Google | I4: Round1 | J4: +91 9920264452 | K4: chetan@weekday.works | L4: <calendly_link> | M4: Yes | R4: =IF(OR(O4="Scheduled",Q4="Scheduled"),"SCHEDULED",IF(Q4="Escalate to call","ESCALATED TO CALL",IF(N4="Bad contact","BAD CONTACT",IF(N4="","NOT STARTED","IN PROGRESS"))))
A5: REQ-0004 | B5: 44867.697 | C5: =B5+1 | D5: =(C5-NOW())*24 | E5: =IF(N5="","STEP 1: Send WhatsApp + Email blast now (Playbook M1)",IF(N5="Bad contact","STOP: report bad contact to lead (Playbook)",IF(O5="Scheduled","DONE: scheduled via Calendly",IF(O5="","STEP 2: Check Calendly now",IF(P5="","STEP 3: Send WhatsApp nudge (Playbook M2)",IF(Q5="Scheduled","DONE: scheduled via Calendly",IF(Q5="Escalate to call","HANDED to Shyam (call queue)","STEP 4: Final Calendly check"))))))) | F5: =IF(N5="",B5,IF(O5="",B5+2/24,IF(AND(O5="Not yet",P5=""),B5+2/24,IF(Q5="",B5+4/24,"")))) | G5: Chetan | H5: Tesla | I5: Round2 | J5: +91 9920264452 | K5: chetan@weekday.works | L5: <calendly_link> | R5: =IF(OR(O5="Scheduled",Q5="Scheduled"),"SCHEDULED",IF(Q5="Escalate to call","ESCALATED TO CALL",IF(N5="Bad contact","BAD CONTACT",IF(N5="","NOT STARTED","IN PROGRESS"))))
A6: REQ-0005 | B6: 44867.702 | C6: =B6+1 | D6: =(C6-NOW())*24 | E6: =IF(N6="","STEP 1: Send WhatsApp + Email blast now (Playbook M1)",IF(N6="Bad contact","STOP: report bad contact to lead (Playbook)",IF(O6="Scheduled","DONE: scheduled via Calendly",IF(O6="","STEP 2: Check Calendly now",IF(P6="","STEP 3: Send WhatsApp nudge (Playbook M2)",IF(Q6="Scheduled","DONE: scheduled via Calendly",IF(Q6="Escalate to call","HANDED to Shyam (call queue)","STEP 4: Final Calendly check"))))))) | F6: =IF(N6="",B6,IF(O6="",B6+2/24,IF(AND(O6="Not yet",P6=""),B6+2/24,IF(Q6="",B6+4/24,"")))) | G6: Chetan | H6: FB | I6: Round1 | J6: +91 9920264452 | K6: chetan@weekday.works | L6: <calendly_link> | R6: =IF(OR(O6="Scheduled",Q6="Scheduled"),"SCHEDULED",IF(Q6="Escalate to call","ESCALATED TO CALL",IF(N6="Bad contact","BAD CONTACT",IF(N6="","NOT STARTED","IN PROGRESS"))))
A7: REQ-0006 | B7: 44867.79 | C7: =B7+1 | D7: =(C7-NOW())*24 | E7: =IF(N7="","STEP 1: Send WhatsApp + Email blast now (Playbook M1)",IF(N7="Bad contact","STOP: report bad contact to lead (Playbook)",IF(O7="Scheduled","DONE: scheduled via Calendly",IF(O7="","STEP 2: Check Calendly now",IF(P7="","STEP 3: Send WhatsApp nudge (Playbook M2)",IF(Q7="Scheduled","DONE: scheduled via Calendly",IF(Q7="Escalate to call","HANDED to Shyam (call queue)","STEP 4: Final Calendly check"))))))) | F7: =IF(N7="",B7,IF(O7="",B7+2/24,IF(AND(O7="Not yet",P7=""),B7+2/24,IF(Q7="",B7+4/24,"")))) | G7: Chetan | H7: Google | I7: Round1 | J7: +91 9920264452 | K7: chetan@weekday.works | L7: <calendly_link> | M7: Yes | R7: =IF(OR(O7="Scheduled",Q7="Scheduled"),"SCHEDULED",IF(Q7="Escalate to call","ESCALATED TO CALL",IF(N7="Bad contact","BAD CONTACT",IF(N7="","NOT STARTED","IN PROGRESS"))))
A8: REQ-0007 | B8: 44867.799 | C8: =B8+1 | D8: =(C8-NOW())*24 | E8: =IF(N8="","STEP 1: Send WhatsApp + Email blast now (Playbook M1)",IF(N8="Bad contact","STOP: report bad contact to lead (Playbook)",IF(O8="Scheduled","DONE: scheduled via Calendly",IF(O8="","STEP 2: Check Calendly now",IF(P8="","STEP 3: Send WhatsApp nudge (Playbook M2)",IF(Q8="Scheduled","DONE: scheduled via Calendly",IF(Q8="Escalate to call","HANDED to Shyam (call queue)","STEP 4: Final Calendly check"))))))) | F8: =IF(N8="",B8,IF(O8="",B8+2/24,IF(AND(O8="Not yet",P8=""),B8+2/24,IF(Q8="",B8+4/24,"")))) | G8: Chetan | H8: FB | I8: Round2 | J8: +91 9920264452 | K8: chetan@weekday.works | L8: <calendly_link> | R8: =IF(OR(O8="Scheduled",Q8="Scheduled"),"SCHEDULED",IF(Q8="Escalate to call","ESCALATED TO CALL",IF(N8="Bad contact","BAD CONTACT",IF(N8="","NOT STARTED","IN PROGRESS"))))
A9: REQ-0008 | B9: 44867.806 | C9: =B9+1 | D9: =(C9-NOW())*24 | E9: =IF(N9="","STEP 1: Send WhatsApp + Email blast now (Playbook M1)",IF(N9="Bad contact","STOP: report bad contact to lead (Playbook)",IF(O9="Scheduled","DONE: scheduled via Calendly",IF(O9="","STEP 2: Check Calendly now",IF(P9="","STEP 3: Send WhatsApp nudge (Playbook M2)",IF(Q9="Scheduled","DONE: scheduled via Calendly",IF(Q9="Escalate to call","HANDED to Shyam (call queue)","STEP 4: Final Calendly check"))))))) | F9: =IF(N9="",B9,IF(O9="",B9+2/24,IF(AND(O9="Not yet",P9=""),B9+2/24,IF(Q9="",B9+4/24,"")))) | G9: Chetan | H9: FB | I9: Round1 | J9: +91 9920264452 | K9: chetan@weekday.works | L9: <calendly_link> | M9: Yes | R9: =IF(OR(O9="Scheduled",Q9="Scheduled"),"SCHEDULED",IF(Q9="Escalate to call","ESCALATED TO CALL",IF(N9="Bad contact","BAD CONTACT",IF(N9="","NOT STARTED","IN PROGRESS"))))
A10: REQ-0009 | B10: 44867.827 | C10: =B10+1 | D10: =(C10-NOW())*24 | E10: =IF(N10="","STEP 1: Send WhatsApp + Email blast now (Playbook M1)",IF(N10="Bad contact","STOP: report bad contact to lead (Playbook)",IF(O10="Scheduled","DONE: scheduled via Calendly",IF(O10="","STEP 2: Check Calendly now",IF(P10="","STEP 3: Send WhatsApp nudge (Playbook M2)",IF(Q10="Scheduled","DONE: scheduled via Calendly",IF(Q10="Escalate to call","HANDED to Shyam (call queue)","STEP 4: Final Calendly check"))))))) | F10: =IF(N10="",B10,IF(O10="",B10+2/24,IF(AND(O10="Not yet",P10=""),B10+2/24,IF(Q10="",B10+4/24,"")))) | G10: Chetan | H10: Google | I10: Round1 | J10: +91 9920264452 | K10: chetan@weekday.works | L10: <calendly_link> | R10: =IF(OR(O10="Scheduled",Q10="Scheduled"),"SCHEDULED",IF(Q10="Escalate to call","ESCALATED TO CALL",IF(N10="Bad contact","BAD CONTACT",IF(N10="","NOT STARTED","IN PROGRESS"))))
A11: REQ-0010 | B11: 44867.827 | C11: =B11+1 | D11: =(C11-NOW())*24 | E11: =IF(N11="","STEP 1: Send WhatsApp + Email blast now (Playbook M1)",IF(N11="Bad contact","STOP: report bad contact to lead (Playbook)",IF(O11="Scheduled","DONE: scheduled via Calendly",IF(O11="","STEP 2: Check Calendly now",IF(P11="","STEP 3: Send WhatsApp nudge (Playbook M2)",IF(Q11="Scheduled","DONE: scheduled via Calendly",IF(Q11="Escalate to call","HANDED to Shyam (call queue)","STEP 4: Final Calendly check"))))))) | F11: =IF(N11="",B11,IF(O11="",B11+2/24,IF(AND(O11="Not yet",P11=""),B11+2/24,IF(Q11="",B11+4/24,"")))) | G11: Chetan | H11: FB | I11: Round2 | J11: +91 9920264452 | K11: chetan@weekday.works | L11: <calendly_link> | M11: Yes | R11: =IF(OR(O11="Scheduled",Q11="Scheduled"),"SCHEDULED",IF(Q11="Escalate to call","ESCALATED TO CALL",IF(N11="Bad contact","BAD CONTACT",IF(N11="","NOT STARTED","IN PROGRESS"))))
A12: REQ-0011 | B12: 44867.827 | C12: =B12+1 | D12: =(C12-NOW())*24 | E12: =IF(N12="","STEP 1: Send WhatsApp + Email blast now (Playbook M1)",IF(N12="Bad contact","STOP: report bad contact to lead (Playbook)",IF(O12="Scheduled","DONE: scheduled via Calendly",IF(O12="","STEP 2: Check Calendly now",IF(P12="","STEP 3: Send WhatsApp nudge (Playbook M2)",IF(Q12="Scheduled","DONE: scheduled via Calendly",IF(Q12="Escalate to call","HANDED to Shyam (call queue)","STEP 4: Final Calendly check"))))))) | F12: =IF(N12="",B12,IF(O12="",B12+2/24,IF(AND(O12="Not yet",P12=""),B12+2/24,IF(Q12="",B12+4/24,"")))) | G12: Chetan | H12: Tesla | I12: Round1 | J12: +91 9920264452 | K12: chetan@weekday.works | L12: <calendly_link> | R12: =IF(OR(O12="Scheduled",Q12="Scheduled"),"SCHEDULED",IF(Q12="Escalate to call","ESCALATED TO CALL",IF(N12="Bad contact","BAD CONTACT",IF(N12="","NOT STARTED","IN PROGRESS"))))
A13: REQ-0012 | B13: 44867.827 | C13: =B13+1 | D13: =(C13-NOW())*24 | E13: =IF(N13="","STEP 1: Send WhatsApp + Email blast now (Playbook M1)",IF(N13="Bad contact","STOP: report bad contact to lead (Playbook)",IF(O13="Scheduled","DONE: scheduled via Calendly",IF(O13="","STEP 2: Check Calendly now",IF(P13="","STEP 3: Send WhatsApp nudge (Playbook M2)",IF(Q13="Scheduled","DONE: scheduled via Calendly",IF(Q13="Escalate to call","HANDED to Shyam (call queue)","STEP 4: Final Calendly check"))))))) | F13: =IF(N13="",B13,IF(O13="",B13+2/24,IF(AND(O13="Not yet",P13=""),B13+2/24,IF(Q13="",B13+4/24,"")))) | G13: Chetan | H13: Tesla | I13: Round1 | J13: +91 9920264452 | K13: chetan@weekday.works | L13: <calendly_link> | M13: Yes | R13: =IF(OR(O13="Scheduled",Q13="Scheduled"),"SCHEDULED",IF(Q13="Escalate to call","ESCALATED TO CALL",IF(N13="Bad contact","BAD CONTACT",IF(N13="","NOT STARTED","IN PROGRESS"))))
A14: REQ-0013 | B14: 44867.827 | C14: =B14+1 | D14: =(C14-NOW())*24 | E14: =IF(N14="","STEP 1: Send WhatsApp + Email blast now (Playbook M1)",IF(N14="Bad contact","STOP: report bad contact to lead (Playbook)",IF(O14="Scheduled","DONE: scheduled via Calendly",IF(O14="","STEP 2: Check Calendly now",IF(P14="","STEP 3: Send WhatsApp nudge (Playbook M2)",IF(Q14="Scheduled","DONE: scheduled via Calendly",IF(Q14="Escalate to call","HANDED to Shyam (call queue)","STEP 4: Final Calendly check"))))))) | F14: =IF(N14="",B14,IF(O14="",B14+2/24,IF(AND(O14="Not yet",P14=""),B14+2/24,IF(Q14="",B14+4/24,"")))) | G14: Chetan | H14: Tesla | I14: Round2 | J14: +91 9920264452 | K14: chetan@weekday.works | L14: <calendly_link> | M14: Yes | R14: =IF(OR(O14="Scheduled",Q14="Scheduled"),"SCHEDULED",IF(Q14="Escalate to call","ESCALATED TO CALL",IF(N14="Bad contact","BAD CONTACT",IF(N14="","NOT STARTED","IN PROGRESS"))))
A15: REQ-0014 | B15: 44867.827 | C15: =B15+1 | D15: =(C15-NOW())*24 | E15: =IF(N15="","STEP 1: Send WhatsApp + Email blast now (Playbook M1)",IF(N15="Bad contact","STOP: report bad contact to lead (Playbook)",IF(O15="Scheduled","DONE: scheduled via Calendly",IF(O15="","STEP 2: Check Calendly now",IF(P15="","STEP 3: Send WhatsApp nudge (Playbook M2)",IF(Q15="Scheduled","DONE: scheduled via Calendly",IF(Q15="Escalate to call","HANDED to Shyam (call queue)","STEP 4: Final Calendly check"))))))) | F15: =IF(N15="",B15,IF(O15="",B15+2/24,IF(AND(O15="Not yet",P15=""),B15+2/24,IF(Q15="",B15+4/24,"")))) | G15: Chetan | H15: Tesla | I15: Round1 | J15: +91 9920264452 | K15: chetan@weekday.works | L15: <calendly_link> | M15: Yes | R15: =IF(OR(O15="Scheduled",Q15="Scheduled"),"SCHEDULED",IF(Q15="Escalate to call","ESCALATED TO CALL",IF(N15="Bad contact","BAD CONTACT",IF(N15="","NOT STARTED","IN PROGRESS"))))
A16: REQ-0015 | B16: 44867.827 | C16: =B16+1 | D16: =(C16-NOW())*24 | E16: =IF(N16="","STEP 1: Send WhatsApp + Email blast now (Playbook M1)",IF(N16="Bad contact","STOP: report bad contact to lead (Playbook)",IF(O16="Scheduled","DONE: scheduled via Calendly",IF(O16="","STEP 2: Check Calendly now",IF(P16="","STEP 3: Send WhatsApp nudge (Playbook M2)",IF(Q16="Scheduled","DONE: scheduled via Calendly",IF(Q16="Escalate to call","HANDED to Shyam (call queue)","STEP 4: Final Calendly check"))))))) | F16: =IF(N16="",B16,IF(O16="",B16+2/24,IF(AND(O16="Not yet",P16=""),B16+2/24,IF(Q16="",B16+4/24,"")))) | G16: Chetan | H16: Tesla | I16: Round1 | J16: +91 9920264452 | K16: chetan@weekday.works | L16: <calendly_link> | M16: Yes | R16: =IF(OR(O16="Scheduled",Q16="Scheduled"),"SCHEDULED",IF(Q16="Escalate to call","ESCALATED TO CALL",IF(N16="Bad contact","BAD CONTACT",IF(N16="","NOT STARTED","IN PROGRESS"))))
A17: REQ-0016 | B17: 44867.827 | C17: =B17+1 | D17: =(C17-NOW())*24 | E17: =IF(N17="","STEP 1: Send WhatsApp + Email blast now (Playbook M1)",IF(N17="Bad contact","STOP: report bad contact to lead (Playbook)",IF(O17="Scheduled","DONE: scheduled via Calendly",IF(O17="","STEP 2: Check Calendly now",IF(P17="","STEP 3: Send WhatsApp nudge (Playbook M2)",IF(Q17="Scheduled","DONE: scheduled via Calendly",IF(Q17="Escalate to call","HANDED to Shyam (call queue)","STEP 4: Final Calendly check"))))))) | F17: =IF(N17="",B17,IF(O17="",B17+2/24,IF(AND(O17="Not yet",P17=""),B17+2/24,IF(Q17="",B17+4/24,"")))) | G17: Chetan | H17: Google | I17: Round1 | J17: +91 9920264452 | K17: chetan@weekday.works | L17: <calendly_link> | M17: Yes | R17: =IF(OR(O17="Scheduled",Q17="Scheduled"),"SCHEDULED",IF(Q17="Escalate to call","ESCALATED TO CALL",IF(N17="Bad contact","BAD CONTACT",IF(N17="","NOT STARTED","IN PROGRESS"))))
A18: REQ-0017 | B18: 44867.827 | C18: =B18+1 | D18: =(C18-NOW())*24 | E18: =IF(N18="","STEP 1: Send WhatsApp + Email blast now (Playbook M1)",IF(N18="Bad contact","STOP: report bad contact to lead (Playbook)",IF(O18="Scheduled","DONE: scheduled via Calendly",IF(O18="","STEP 2: Check Calendly now",IF(P18="","STEP 3: Send WhatsApp nudge (Playbook M2)",IF(Q18="Scheduled","DONE: scheduled via Calendly",IF(Q18="Escalate to call","HANDED to Shyam (call queue)","STEP 4: Final Calendly check"))))))) | F18: =IF(N18="",B18,IF(O18="",B18+2/24,IF(AND(O18="Not yet",P18=""),B18+2/24,IF(Q18="",B18+4/24,"")))) | G18: Chetan | H18: Google | I18: Round3 | J18: +91 9920264452 | K18: chetan@weekday.works | L18: <calendly_link> | R18: =IF(OR(O18="Scheduled",Q18="Scheduled"),"SCHEDULED",IF(Q18="Escalate to call","ESCALATED TO CALL",IF(N18="Bad contact","BAD CONTACT",IF(N18="","NOT STARTED","IN PROGRESS"))))
A19: REQ-0018 | B19: 44867.827 | C19: =B19+1 | D19: =(C19-NOW())*24 | E19: =IF(N19="","STEP 1: Send WhatsApp + Email blast now (Playbook M1)",IF(N19="Bad contact","STOP: report bad contact to lead (Playbook)",IF(O19="Scheduled","DONE: scheduled via Calendly",IF(O19="","STEP 2: Check Calendly now",IF(P19="","STEP 3: Send WhatsApp nudge (Playbook M2)",IF(Q19="Scheduled","DONE: scheduled via Calendly",IF(Q19="Escalate to call","HANDED to Shyam (call queue)","STEP 4: Final Calendly check"))))))) | F19: =IF(N19="",B19,IF(O19="",B19+2/24,IF(AND(O19="Not yet",P19=""),B19+2/24,IF(Q19="",B19+4/24,"")))) | G19: Chetan | H19: Google | I19: Round2 | J19: +91 9920264452 | K19: chetan@weekday.works | L19: <calendly_link> | R19: =IF(OR(O19="Scheduled",Q19="Scheduled"),"SCHEDULED",IF(Q19="Escalate to call","ESCALATED TO CALL",IF(N19="Bad contact","BAD CONTACT",IF(N19="","NOT STARTED","IN PROGRESS"))))
A20: REQ-0019 | B20: 44867.827 | C20: =B20+1 | D20: =(C20-NOW())*24 | E20: =IF(N20="","STEP 1: Send WhatsApp + Email blast now (Playbook M1)",IF(N20="Bad contact","STOP: report bad contact to lead (Playbook)",IF(O20="Scheduled","DONE: scheduled via Calendly",IF(O20="","STEP 2: Check Calendly now",IF(P20="","STEP 3: Send WhatsApp nudge (Playbook M2)",IF(Q20="Scheduled","DONE: scheduled via Calendly",IF(Q20="Escalate to call","HANDED to Shyam (call queue)","STEP 4: Final Calendly check"))))))) | F20: =IF(N20="",B20,IF(O20="",B20+2/24,IF(AND(O20="Not yet",P20=""),B20+2/24,IF(Q20="",B20+4/24,"")))) | G20: Chetan | H20: Google | I20: Round1 | J20: +91 9920264452 | K20: chetan@weekday.works | L20: <calendly_link> | M20: Yes | R20: =IF(OR(O20="Scheduled",Q20="Scheduled"),"SCHEDULED",IF(Q20="Escalate to call","ESCALATED TO CALL",IF(N20="Bad contact","BAD CONTACT",IF(N20="","NOT STARTED","IN PROGRESS"))))
A21: REQ-0020 | B21: 44867.827 | C21: =B21+1 | D21: =(C21-NOW())*24 | E21: =IF(N21="","STEP 1: Send WhatsApp + Email blast now (Playbook M1)",IF(N21="Bad contact","STOP: report bad contact to lead (Playbook)",IF(O21="Scheduled","DONE: scheduled via Calendly",IF(O21="","STEP 2: Check Calendly now",IF(P21="","STEP 3: Send WhatsApp nudge (Playbook M2)",IF(Q21="Scheduled","DONE: scheduled via Calendly",IF(Q21="Escalate to call","HANDED to Shyam (call queue)","STEP 4: Final Calendly check"))))))) | F21: =IF(N21="",B21,IF(O21="",B21+2/24,IF(AND(O21="Not yet",P21=""),B21+2/24,IF(Q21="",B21+4/24,"")))) | G21: Chetan | H21: Reliance | I21: Round1 | J21: +91 9920264452 | K21: chetan@weekday.works | L21: <calendly_link> | R21: =IF(OR(O21="Scheduled",Q21="Scheduled"),"SCHEDULED",IF(Q21="Escalate to call","ESCALATED TO CALL",IF(N21="Bad contact","BAD CONTACT",IF(N21="","NOT STARTED","IN PROGRESS"))))
A22: REQ-0021 | B22: 44867.827 | C22: =B22+1 | D22: =(C22-NOW())*24 | E22: =IF(N22="","STEP 1: Send WhatsApp + Email blast now (Playbook M1)",IF(N22="Bad contact","STOP: report bad contact to lead (Playbook)",IF(O22="Scheduled","DONE: scheduled via Calendly",IF(O22="","STEP 2: Check Calendly now",IF(P22="","STEP 3: Send WhatsApp nudge (Playbook M2)",IF(Q22="Scheduled","DONE: scheduled via Calendly",IF(Q22="Escalate to call","HANDED to Shyam (call queue)","STEP 4: Final Calendly check"))))))) | F22: =IF(N22="",B22,IF(O22="",B22+2/24,IF(AND(O22="Not yet",P22=""),B22+2/24,IF(Q22="",B22+4/24,"")))) | G22: Chetan | H22: Reliance | I22: Round1 | J22: +91 9920264452 | K22: chetan@weekday.works | L22: <calendly_link> | M22: Yes | R22: =IF(OR(O22="Scheduled",Q22="Scheduled"),"SCHEDULED",IF(Q22="Escalate to call","ESCALATED TO CALL",IF(N22="Bad contact","BAD CONTACT",IF(N22="","NOT STARTED","IN PROGRESS"))))
A23: REQ-0022 | B23: 44867.827 | C23: =B23+1 | D23: =(C23-NOW())*24 | E23: =IF(N23="","STEP 1: Send WhatsApp + Email blast now (Playbook M1)",IF(N23="Bad contact","STOP: report bad contact to lead (Playbook)",IF(O23="Scheduled","DONE: scheduled via Calendly",IF(O23="","STEP 2: Check Calendly now",IF(P23="","STEP 3: Send WhatsApp nudge (Playbook M2)",IF(Q23="Scheduled","DONE: scheduled via Calendly",IF(Q23="Escalate to call","HANDED to Shyam (call queue)","STEP 4: Final Calendly check"))))))) | F23: =IF(N23="",B23,IF(O23="",B23+2/24,IF(AND(O23="Not yet",P23=""),B23+2/24,IF(Q23="",B23+4/24,"")))) | G23: Chetan | H23: Reliance | I23: Round2 | J23: +91 9920264452 | K23: chetan@weekday.works | L23: <calendly_link> | R23: =IF(OR(O23="Scheduled",Q23="Scheduled"),"SCHEDULED",IF(Q23="Escalate to call","ESCALATED TO CALL",IF(N23="Bad contact","BAD CONTACT",IF(N23="","NOT STARTED","IN PROGRESS"))))
A24: REQ-0023 | B24: 44867.827 | C24: =B24+1 | D24: =(C24-NOW())*24 | E24: =IF(N24="","STEP 1: Send WhatsApp + Email blast now (Playbook M1)",IF(N24="Bad contact","STOP: report bad contact to lead (Playbook)",IF(O24="Scheduled","DONE: scheduled via Calendly",IF(O24="","STEP 2: Check Calendly now",IF(P24="","STEP 3: Send WhatsApp nudge (Playbook M2)",IF(Q24="Scheduled","DONE: scheduled via Calendly",IF(Q24="Escalate to call","HANDED to Shyam (call queue)","STEP 4: Final Calendly check"))))))) | F24: =IF(N24="",B24,IF(O24="",B24+2/24,IF(AND(O24="Not yet",P24=""),B24+2/24,IF(Q24="",B24+4/24,"")))) | G24: Chetan | H24: Reliance | I24: Round3 | J24: +91 9920264452 | K24: chetan@weekday.works | L24: <calendly_link> | R24: =IF(OR(O24="Scheduled",Q24="Scheduled"),"SCHEDULED",IF(Q24="Escalate to call","ESCALATED TO CALL",IF(N24="Bad contact","BAD CONTACT",IF(N24="","NOT STARTED","IN PROGRESS"))))
A25: REQ-0024 | B25: 44867.827 | C25: =B25+1 | D25: =(C25-NOW())*24 | E25: =IF(N25="","STEP 1: Send WhatsApp + Email blast now (Playbook M1)",IF(N25="Bad contact","STOP: report bad contact to lead (Playbook)",IF(O25="Scheduled","DONE: scheduled via Calendly",IF(O25="","STEP 2: Check Calendly now",IF(P25="","STEP 3: Send WhatsApp nudge (Playbook M2)",IF(Q25="Scheduled","DONE: scheduled via Calendly",IF(Q25="Escalate to call","HANDED to Shyam (call queue)","STEP 4: Final Calendly check"))))))) | F25: =IF(N25="",B25,IF(O25="",B25+2/24,IF(AND(O25="Not yet",P25=""),B25+2/24,IF(Q25="",B25+4/24,"")))) | G25: Chetan | H25: Reliance | I25: Round1 | J25: +91 9920264452 | K25: chetan@weekday.works | L25: <calendly_link> | M25: Yes | R25: =IF(OR(O25="Scheduled",Q25="Scheduled"),"SCHEDULED",IF(Q25="Escalate to call","ESCALATED TO CALL",IF(N25="Bad contact","BAD CONTACT",IF(N25="","NOT STARTED","IN PROGRESS"))))
A26: REQ-0025 | B26: 44867.827 | C26: =B26+1 | D26: =(C26-NOW())*24 | E26: =IF(N26="","STEP 1: Send WhatsApp + Email blast now (Playbook M1)",IF(N26="Bad contact","STOP: report bad contact to lead (Playbook)",IF(O26="Scheduled","DONE: scheduled via Calendly",IF(O26="","STEP 2: Check Calendly now",IF(P26="","STEP 3: Send WhatsApp nudge (Playbook M2)",IF(Q26="Scheduled","DONE: scheduled via Calendly",IF(Q26="Escalate to call","HANDED to Shyam (call queue)","STEP 4: Final Calendly check"))))))) | F26: =IF(N26="",B26,IF(O26="",B26+2/24,IF(AND(O26="Not yet",P26=""),B26+2/24,IF(Q26="",B26+4/24,"")))) | G26: Chetan | H26: Reliance | I26: Round1 | J26: +91 9920264452 | K26: chetan@weekday.works | L26: <calendly_link> | M26: Yes | R26: =IF(OR(O26="Scheduled",Q26="Scheduled"),"SCHEDULED",IF(Q26="Escalate to call","ESCALATED TO CALL",IF(N26="Bad contact","BAD CONTACT",IF(N26="","NOT STARTED","IN PROGRESS"))))
A27: REQ-0026 | B27: 44867.827 | C27: =B27+1 | D27: =(C27-NOW())*24 | E27: =IF(N27="","STEP 1: Send WhatsApp + Email blast now (Playbook M1)",IF(N27="Bad contact","STOP: report bad contact to lead (Playbook)",IF(O27="Scheduled","DONE: scheduled via Calendly",IF(O27="","STEP 2: Check Calendly now",IF(P27="","STEP 3: Send WhatsApp nudge (Playbook M2)",IF(Q27="Scheduled","DONE: scheduled via Calendly",IF(Q27="Escalate to call","HANDED to Shyam (call queue)","STEP 4: Final Calendly check"))))))) | F27: =IF(N27="",B27,IF(O27="",B27+2/24,IF(AND(O27="Not yet",P27=""),B27+2/24,IF(Q27="",B27+4/24,"")))) | G27: Chetan | H27: Reliance | I27: Round1 | J27: +91 9920264452 | K27: chetan@weekday.works | L27: <calendly_link> | M27: Yes | R27: =IF(OR(O27="Scheduled",Q27="Scheduled"),"SCHEDULED",IF(Q27="Escalate to call","ESCALATED TO CALL",IF(N27="Bad contact","BAD CONTACT",IF(N27="","NOT STARTED","IN PROGRESS"))))
A28: REQ-0027 | B28: 44867.827 | C28: =B28+1 | D28: =(C28-NOW())*24 | E28: =IF(N28="","STEP 1: Send WhatsApp + Email blast now (Playbook M1)",IF(N28="Bad contact","STOP: report bad contact to lead (Playbook)",IF(O28="Scheduled","DONE: scheduled via Calendly",IF(O28="","STEP 2: Check Calendly now",IF(P28="","STEP 3: Send WhatsApp nudge (Playbook M2)",IF(Q28="Scheduled","DONE: scheduled via Calendly",IF(Q28="Escalate to call","HANDED to Shyam (call queue)","STEP 4: Final Calendly check"))))))) | F28: =IF(N28="",B28,IF(O28="",B28+2/24,IF(AND(O28="Not yet",P28=""),B28+2/24,IF(Q28="",B28+4/24,"")))) | G28: Chetan | H28: Google | I28: Round3 | J28: +91 9920264452 | K28: chetan@weekday.works | L28: <calendly_link> | M28: Yes | R28: =IF(OR(O28="Scheduled",Q28="Scheduled"),"SCHEDULED",IF(Q28="Escalate to call","ESCALATED TO CALL",IF(N28="Bad contact","BAD CONTACT",IF(N28="","NOT STARTED","IN PROGRESS"))))
A29: REQ-0028 | B29: 44867.827 | C29: =B29+1 | D29: =(C29-NOW())*24 | E29: =IF(N29="","STEP 1: Send WhatsApp + Email blast now (Playbook M1)",IF(N29="Bad contact","STOP: report bad contact to lead (Playbook)",IF(O29="Scheduled","DONE: scheduled via Calendly",IF(O29="","STEP 2: Check Calendly now",IF(P29="","STEP 3: Send WhatsApp nudge (Playbook M2)",IF(Q29="Scheduled","DONE: scheduled via Calendly",IF(Q29="Escalate to call","HANDED to Shyam (call queue)","STEP 4: Final Calendly check"))))))) | F29: =IF(N29="",B29,IF(O29="",B29+2/24,IF(AND(O29="Not yet",P29=""),B29+2/24,IF(Q29="",B29+4/24,"")))) | G29: Chetan | H29: Google | I29: Round1 | J29: +91 9920264452 | K29: chetan@weekday.works | L29: <calendly_link> | M29: Yes | R29: =IF(OR(O29="Scheduled",Q29="Scheduled"),"SCHEDULED",IF(Q29="Escalate to call","ESCALATED TO CALL",IF(N29="Bad contact","BAD CONTACT",IF(N29="","NOT STARTED","IN PROGRESS"))))
A30: REQ-0029 | B30: 44867.827 | C30: =B30+1 | D30: =(C30-NOW())*24 | E30: =IF(N30="","STEP 1: Send WhatsApp + Email blast now (Playbook M1)",IF(N30="Bad contact","STOP: report bad contact to lead (Playbook)",IF(O30="Scheduled","DONE: scheduled via Calendly",IF(O30="","STEP 2: Check Calendly now",IF(P30="","STEP 3: Send WhatsApp nudge (Playbook M2)",IF(Q30="Scheduled","DONE: scheduled via Calendly",IF(Q30="Escalate to call","HANDED to Shyam (call queue)","STEP 4: Final Calendly check"))))))) | F30: =IF(N30="",B30,IF(O30="",B30+2/24,IF(AND(O30="Not yet",P30=""),B30+2/24,IF(Q30="",B30+4/24,"")))) | G30: Chetan | H30: Google | I30: Round1 | J30: +91 9920264452 | K30: chetan@weekday.works | L30: <calendly_link> | M30: Yes | R30: =IF(OR(O30="Scheduled",Q30="Scheduled"),"SCHEDULED",IF(Q30="Escalate to call","ESCALATED TO CALL",IF(N30="Bad contact","BAD CONTACT",IF(N30="","NOT STARTED","IN PROGRESS"))))
A31: REQ-0030 | B31: 44867.827 | C31: =B31+1 | D31: =(C31-NOW())*24 | E31: =IF(N31="","STEP 1: Send WhatsApp + Email blast now (Playbook M1)",IF(N31="Bad contact","STOP: report bad contact to lead (Playbook)",IF(O31="Scheduled","DONE: scheduled via Calendly",IF(O31="","STEP 2: Check Calendly now",IF(P31="","STEP 3: Send WhatsApp nudge (Playbook M2)",IF(Q31="Scheduled","DONE: scheduled via Calendly",IF(Q31="Escalate to call","HANDED to Shyam (call queue)","STEP 4: Final Calendly check"))))))) | F31: =IF(N31="",B31,IF(O31="",B31+2/24,IF(AND(O31="Not yet",P31=""),B31+2/24,IF(Q31="",B31+4/24,"")))) | G31: Chetan | H31: Google | I31: Round1 | J31: +91 9920264452 | K31: chetan@weekday.works | L31: <calendly_link> | M31: Yes | R31: =IF(OR(O31="Scheduled",Q31="Scheduled"),"SCHEDULED",IF(Q31="Escalate to call","ESCALATED TO CALL",IF(N31="Bad contact","BAD CONTACT",IF(N31="","NOT STARTED","IN PROGRESS"))))
A32: REQ-0031 | B32: 44867.827 | C32: =B32+1 | D32: =(C32-NOW())*24 | E32: =IF(N32="","STEP 1: Send WhatsApp + Email blast now (Playbook M1)",IF(N32="Bad contact","STOP: report bad contact to lead (Playbook)",IF(O32="Scheduled","DONE: scheduled via Calendly",IF(O32="","STEP 2: Check Calendly now",IF(P32="","STEP 3: Send WhatsApp nudge (Playbook M2)",IF(Q32="Scheduled","DONE: scheduled via Calendly",IF(Q32="Escalate to call","HANDED to Shyam (call queue)","STEP 4: Final Calendly check"))))))) | F32: =IF(N32="",B32,IF(O32="",B32+2/24,IF(AND(O32="Not yet",P32=""),B32+2/24,IF(Q32="",B32+4/24,"")))) | G32: Chetan | H32: Google | I32: Round1 | J32: +91 9920264452 | K32: chetan@weekday.works | L32: <calendly_link> | M32: Yes | R32: =IF(OR(O32="Scheduled",Q32="Scheduled"),"SCHEDULED",IF(Q32="Escalate to call","ESCALATED TO CALL",IF(N32="Bad contact","BAD CONTACT",IF(N32="","NOT STARTED","IN PROGRESS"))))
A33: REQ-0032 | B33: 44867.827 | C33: =B33+1 | D33: =(C33-NOW())*24 | E33: =IF(N33="","STEP 1: Send WhatsApp + Email blast now (Playbook M1)",IF(N33="Bad contact","STOP: report bad contact to lead (Playbook)",IF(O33="Scheduled","DONE: scheduled via Calendly",IF(O33="","STEP 2: Check Calendly now",IF(P33="","STEP 3: Send WhatsApp nudge (Playbook M2)",IF(Q33="Scheduled","DONE: scheduled via Calendly",IF(Q33="Escalate to call","HANDED to Shyam (call queue)","STEP 4: Final Calendly check"))))))) | F33: =IF(N33="",B33,IF(O33="",B33+2/24,IF(AND(O33="Not yet",P33=""),B33+2/24,IF(Q33="",B33+4/24,"")))) | G33: Chetan | H33: Google | I33: Round3 | J33: +91 9920264452 | K33: chetan@weekday.works | L33: <calendly_link> | M33: Yes | R33: =IF(OR(O33="Scheduled",Q33="Scheduled"),"SCHEDULED",IF(Q33="Escalate to call","ESCALATED TO CALL",IF(N33="Bad contact","BAD CONTACT",IF(N33="","NOT STARTED","IN PROGRESS"))))
A34: REQ-0033 | B34: 44867.827 | C34: =B34+1 | D34: =(C34-NOW())*24 | E34: =IF(N34="","STEP 1: Send WhatsApp + Email blast now (Playbook M1)",IF(N34="Bad contact","STOP: report bad contact to lead (Playbook)",IF(O34="Scheduled","DONE: scheduled via Calendly",IF(O34="","STEP 2: Check Calendly now",IF(P34="","STEP 3: Send WhatsApp nudge (Playbook M2)",IF(Q34="Scheduled","DONE: scheduled via Calendly",IF(Q34="Escalate to call","HANDED to Shyam (call queue)","STEP 4: Final Calendly check"))))))) | F34: =IF(N34="",B34,IF(O34="",B34+2/24,IF(AND(O34="Not yet",P34=""),B34+2/24,IF(Q34="",B34+4/24,"")))) | G34: Chetan | H34: Google | I34: Round1 | J34: +91 9920264452 | K34: chetan@weekday.works | L34: <calendly_link> | M34: Yes | R34: =IF(OR(O34="Scheduled",Q34="Scheduled"),"SCHEDULED",IF(Q34="Escalate to call","ESCALATED TO CALL",IF(N34="Bad contact","BAD CONTACT",IF(N34="","NOT STARTED","IN PROGRESS"))))
A35: REQ-0034 | B35: 44867.827 | C35: =B35+1 | D35: =(C35-NOW())*24 | E35: =IF(N35="","STEP 1: Send WhatsApp + Email blast now (Playbook M1)",IF(N35="Bad contact","STOP: report bad contact to lead (Playbook)",IF(O35="Scheduled","DONE: scheduled via Calendly",IF(O35="","STEP 2: Check Calendly now",IF(P35="","STEP 3: Send WhatsApp nudge (Playbook M2)",IF(Q35="Scheduled","DONE: scheduled via Calendly",IF(Q35="Escalate to call","HANDED to Shyam (call queue)","STEP 4: Final Calendly check"))))))) | F35: =IF(N35="",B35,IF(O35="",B35+2/24,IF(AND(O35="Not yet",P35=""),B35+2/24,IF(Q35="",B35+4/24,"")))) | G35: Chetan | H35: Google | I35: Round1 | J35: +91 9920264452 | K35: chetan@weekday.works | L35: <calendly_link> | M35: Yes | R35: =IF(OR(O35="Scheduled",Q35="Scheduled"),"SCHEDULED",IF(Q35="Escalate to call","ESCALATED TO CALL",IF(N35="Bad contact","BAD CONTACT",IF(N35="","NOT STARTED","IN PROGRESS"))))
A36: REQ-0035 | B36: 44867.827 | C36: =B36+1 | D36: =(C36-NOW())*24 | E36: =IF(N36="","STEP 1: Send WhatsApp + Email blast now (Playbook M1)",IF(N36="Bad contact","STOP: report bad contact to lead (Playbook)",IF(O36="Scheduled","DONE: scheduled via Calendly",IF(O36="","STEP 2: Check Calendly now",IF(P36="","STEP 3: Send WhatsApp nudge (Playbook M2)",IF(Q36="Scheduled","DONE: scheduled via Calendly",IF(Q36="Escalate to call","HANDED to Shyam (call queue)","STEP 4: Final Calendly check"))))))) | F36: =IF(N36="",B36,IF(O36="",B36+2/24,IF(AND(O36="Not yet",P36=""),B36+2/24,IF(Q36="",B36+4/24,"")))) | G36: Chetan | H36: Google | I36: Round1 | J36: +91 9920264452 | K36: chetan@weekday.works | L36: <calendly_link> | M36: Yes | R36: =IF(OR(O36="Scheduled",Q36="Scheduled"),"SCHEDULED",IF(Q36="Escalate to call","ESCALATED TO CALL",IF(N36="Bad contact","BAD CONTACT",IF(N36="","NOT STARTED","IN PROGRESS"))))
... A516: REQ-0515 | B516: 44867.827 | C516: =B516+1 | D516: =(C516-NOW())*24 | E516: =IF(N516="","STEP 1: Send WhatsApp + Email blast now (Playbook M1)",IF(N516="Bad contact","STOP: report bad contact to lead (Playbook)",IF(O516="Scheduled","DONE: scheduled via Calendly",IF(O516="","STEP 2: Check Calendly now",IF(P516="","STEP 3: Send WhatsApp nudge (Playbook M2)",IF(Q516="Scheduled","DONE: scheduled via Calendly",IF(Q516="Escalate to call","HANDED to Shyam (call queue)","STEP 4: Final Calendly check"))))))) | F516: =IF(N516="",B516,IF(O516="",B516+2/24,IF(AND(O516="Not yet",P516=""),B516+2/24,IF(Q516="",B516+4/24,"")))) | G516: Chetan | H516: Google | I516: Round1 | J516: +91 9920264452 | K516: chetan@weekday.works | L516: <calendly_link> | M516: Yes | R516: =IF(OR(O516="Scheduled",Q516="Scheduled"),"SCHEDULED",IF(Q516="Escalate to call","ESCALATED TO CALL",IF(N516="Bad contact","BAD CONTACT",IF(N516="","NOT STARTED","IN PROGRESS"))))

Sheet Shyam - Call ToDo
A1: Req ID | B1: Added On | C1: SLA Deadline | D1: Hours Left | E1: NEEDS CALL? | F1: NEXT STEP | G1: Call By | H1: Candidate | I1: Company | J1: Round | K1: Phone | L1: Calendly Link (this round) | M1: Call 1 | N1: Call 2 | O1: Shyam Status | P1: FINAL OUTCOME | Q1: Notes
A2: REQ-0001 | B2: 44867.452 | C2: =B2+1 | D2: =(C2-NOW())*24 | E2: =IF('Ram - Digital ToDo'!Q2="Escalate to call","CALL NOW",IF('Ram - Digital ToDo'!N2="Bad contact","CALL NOW (digital failed)","Ram is handling - no action")) | F2: =IF(E2="Ram is handling - no action","No action needed",IF(M2="","CALL 1: ring candidate, offer to book on call (Playbook C1)",IF(OR(M2="Scheduled on call",M2="Booked on their behalf"),"DONE: scheduled on call",IF(M2="Not interested/Declined","CLOSED: candidate declined (log + tell lead)",IF(N2="","CALL 2: final attempt (Playbook C2)",IF(OR(N2="Scheduled on call",N2="Booked on their behalf"),"DONE: scheduled on call",IF(N2="Escalate to AM","ESCALATED TO LEAD","Review"))))))) | G2: =IF(E2="Ram is handling - no action","",IF(M2="",B2+6/24,IF(AND(M2<>"Scheduled on call",M2<>"Booked on their behalf",M2<>"Not interested/Declined",N2=""),B2+20/24,""))) | H2: Chetan | I2: FB | J2: Round2 | K2: +91 9920264452 | L2: <calendly_link> | O2: =IF(OR(M2="Scheduled on call",M2="Booked on their behalf",N2="Scheduled on call",N2="Booked on their behalf"),"SCHEDULED (call)",IF(OR(M2="Not interested/Declined",N2="Not interested/Declined"),"DECLINED",IF(N2="Escalate to AM","ESCALATED TO LEAD",IF(E2="Ram is handling - no action","N/A",IF(M2="","PENDING CALL 1","IN PROGRESS"))))) | P2: =IF(OR('Ram - Digital ToDo'!O2="Scheduled",'Ram - Digital ToDo'!Q2="Scheduled"),"Scheduled within SLA (self-serve)",IF(OR(M2="Scheduled on call",M2="Booked on their behalf",N2="Scheduled on call",N2="Booked on their behalf"),"Scheduled within SLA (call)",IF(OR(M2="Not interested/Declined",N2="Not interested/Declined"),"Declined",IF(N2="Escalate to AM","SLA breach - unresolved","In progress"))))
A3: REQ-0002 | B3: 44867.494 | C3: =B3+1 | D3: =(C3-NOW())*24 | E3: =IF('Ram - Digital ToDo'!Q3="Escalate to call","CALL NOW",IF('Ram - Digital ToDo'!N3="Bad contact","CALL NOW (digital failed)","Ram is handling - no action")) | F3: =IF(E3="Ram is handling - no action","No action needed",IF(M3="","CALL 1: ring candidate, offer to book on call (Playbook C1)",IF(OR(M3="Scheduled on call",M3="Booked on their behalf"),"DONE: scheduled on call",IF(M3="Not interested/Declined","CLOSED: candidate declined (log + tell lead)",IF(N3="","CALL 2: final attempt (Playbook C2)",IF(OR(N3="Scheduled on call",N3="Booked on their behalf"),"DONE: scheduled on call",IF(N3="Escalate to AM","ESCALATED TO LEAD","Review"))))))) | G3: =IF(E3="Ram is handling - no action","",IF(M3="",B3+6/24,IF(AND(M3<>"Scheduled on call",M3<>"Booked on their behalf",M3<>"Not interested/Declined",N3=""),B3+20/24,""))) | H3: Chetan | I3: Tesla | J3: Round3 | K3: +91 9920264452 | L3: <calendly_link> | O3: =IF(OR(M3="Scheduled on call",M3="Booked on their behalf",N3="Scheduled on call",N3="Booked on their behalf"),"SCHEDULED (call)",IF(OR(M3="Not interested/Declined",N3="Not interested/Declined"),"DECLINED",IF(N3="Escalate to AM","ESCALATED TO LEAD",IF(E3="Ram is handling - no action","N/A",IF(M3="","PENDING CALL 1","IN PROGRESS"))))) | P3: =IF(OR('Ram - Digital ToDo'!O3="Scheduled",'Ram - Digital ToDo'!Q3="Scheduled"),"Scheduled within SLA (self-serve)",IF(OR(M3="Scheduled on call",M3="Booked on their behalf",N3="Scheduled on call",N3="Booked on their behalf"),"Scheduled within SLA (call)",IF(OR(M3="Not interested/Declined",N3="Not interested/Declined"),"Declined",IF(N3="Escalate to AM","SLA breach - unresolved","In progress"))))
A4: REQ-0003 | B4: 44867.619 | C4: =B4+1 | D4: =(C4-NOW())*24 | E4: =IF('Ram - Digital ToDo'!Q4="Escalate to call","CALL NOW",IF('Ram - Digital ToDo'!N4="Bad contact","CALL NOW (digital failed)","Ram is handling - no action")) | F4: =IF(E4="Ram is handling - no action","No action needed",IF(M4="","CALL 1: ring candidate, offer to book on call (Playbook C1)",IF(OR(M4="Scheduled on call",M4="Booked on their behalf"),"DONE: scheduled on call",IF(M4="Not interested/Declined","CLOSED: candidate declined (log + tell lead)",IF(N4="","CALL 2: final attempt (Playbook C2)",IF(OR(N4="Scheduled on call",N4="Booked on their behalf"),"DONE: scheduled on call",IF(N4="Escalate to AM","ESCALATED TO LEAD","Review"))))))) | G4: =IF(E4="Ram is handling - no action","",IF(M4="",B4+6/24,IF(AND(M4<>"Scheduled on call",M4<>"Booked on their behalf",M4<>"Not interested/Declined",N4=""),B4+20/24,""))) | H4: Chetan | I4: Google | J4: Round1 | K4: +91 9920264452 | L4: <calendly_link> | O4: =IF(OR(M4="Scheduled on call",M4="Booked on their behalf",N4="Scheduled on call",N4="Booked on their behalf"),"SCHEDULED (call)",IF(OR(M4="Not interested/Declined",N4="Not interested/Declined"),"DECLINED",IF(N4="Escalate to AM","ESCALATED TO LEAD",IF(E4="Ram is handling - no action","N/A",IF(M4="","PENDING CALL 1","IN PROGRESS"))))) | P4: =IF(OR('Ram - Digital ToDo'!O4="Scheduled",'Ram - Digital ToDo'!Q4="Scheduled"),"Scheduled within SLA (self-serve)",IF(OR(M4="Scheduled on call",M4="Booked on their behalf",N4="Scheduled on call",N4="Booked on their behalf"),"Scheduled within SLA (call)",IF(OR(M4="Not interested/Declined",N4="Not interested/Declined"),"Declined",IF(N4="Escalate to AM","SLA breach - unresolved","In progress"))))
A5: REQ-0004 | B5: 44867.697 | C5: =B5+1 | D5: =(C5-NOW())*24 | E5: =IF('Ram - Digital ToDo'!Q5="Escalate to call","CALL NOW",IF('Ram - Digital ToDo'!N5="Bad contact","CALL NOW (digital failed)","Ram is handling - no action")) | F5: =IF(E5="Ram is handling - no action","No action needed",IF(M5="","CALL 1: ring candidate, offer to book on call (Playbook C1)",IF(OR(M5="Scheduled on call",M5="Booked on their behalf"),"DONE: scheduled on call",IF(M5="Not interested/Declined","CLOSED: candidate declined (log + tell lead)",IF(N5="","CALL 2: final attempt (Playbook C2)",IF(OR(N5="Scheduled on call",N5="Booked on their behalf"),"DONE: scheduled on call",IF(N5="Escalate to AM","ESCALATED TO LEAD","Review"))))))) | G5: =IF(E5="Ram is handling - no action","",IF(M5="",B5+6/24,IF(AND(M5<>"Scheduled on call",M5<>"Booked on their behalf",M5<>"Not interested/Declined",N5=""),B5+20/24,""))) | H5: Chetan | I5: Tesla | J5: Round2 | K5: +91 9920264452 | L5: <calendly_link> | O5: =IF(OR(M5="Scheduled on call",M5="Booked on their behalf",N5="Scheduled on call",N5="Booked on their behalf"),"SCHEDULED (call)",IF(OR(M5="Not interested/Declined",N5="Not interested/Declined"),"DECLINED",IF(N5="Escalate to AM","ESCALATED TO LEAD",IF(E5="Ram is handling - no action","N/A",IF(M5="","PENDING CALL 1","IN PROGRESS"))))) | P5: =IF(OR('Ram - Digital ToDo'!O5="Scheduled",'Ram - Digital ToDo'!Q5="Scheduled"),"Scheduled within SLA (self-serve)",IF(OR(M5="Scheduled on call",M5="Booked on their behalf",N5="Scheduled on call",N5="Booked on their behalf"),"Scheduled within SLA (call)",IF(OR(M5="Not interested/Declined",N5="Not interested/Declined"),"Declined",IF(N5="Escalate to AM","SLA breach - unresolved","In progress"))))
A6: REQ-0005 | B6: 44867.702 | C6: =B6+1 | D6: =(C6-NOW())*24 | E6: =IF('Ram - Digital ToDo'!Q6="Escalate to call","CALL NOW",IF('Ram - Digital ToDo'!N6="Bad contact","CALL NOW (digital failed)","Ram is handling - no action")) | F6: =IF(E6="Ram is handling - no action","No action needed",IF(M6="","CALL 1: ring candidate, offer to book on call (Playbook C1)",IF(OR(M6="Scheduled on call",M6="Booked on their behalf"),"DONE: scheduled on call",IF(M6="Not interested/Declined","CLOSED: candidate declined (log + tell lead)",IF(N6="","CALL 2: final attempt (Playbook C2)",IF(OR(N6="Scheduled on call",N6="Booked on their behalf"),"DONE: scheduled on call",IF(N6="Escalate to AM","ESCALATED TO LEAD","Review"))))))) | G6: =IF(E6="Ram is handling - no action","",IF(M6="",B6+6/24,IF(AND(M6<>"Scheduled on call",M6<>"Booked on their behalf",M6<>"Not interested/Declined",N6=""),B6+20/24,""))) | H6: Chetan | I6: FB | J6: Round1 | K6: +91 9920264452 | L6: <calendly_link> | O6: =IF(OR(M6="Scheduled on call",M6="Booked on their behalf",N6="Scheduled on call",N6="Booked on their behalf"),"SCHEDULED (call)",IF(OR(M6="Not interested/Declined",N6="Not interested/Declined"),"DECLINED",IF(N6="Escalate to AM","ESCALATED TO LEAD",IF(E6="Ram is handling - no action","N/A",IF(M6="","PENDING CALL 1","IN PROGRESS"))))) | P6: =IF(OR('Ram - Digital ToDo'!O6="Scheduled",'Ram - Digital ToDo'!Q6="Scheduled"),"Scheduled within SLA (self-serve)",IF(OR(M6="Scheduled on call",M6="Booked on their behalf",N6="Scheduled on call",N6="Booked on their behalf"),"Scheduled within SLA (call)",IF(OR(M6="Not interested/Declined",N6="Not interested/Declined"),"Declined",IF(N6="Escalate to AM","SLA breach - unresolved","In progress"))))
A7: REQ-0006 | B7: 44867.79 | C7: =B7+1 | D7: =(C7-NOW())*24 | E7: =IF('Ram - Digital ToDo'!Q7="Escalate to call","CALL NOW",IF('Ram - Digital ToDo'!N7="Bad contact","CALL NOW (digital failed)","Ram is handling - no action")) | F7: =IF(E7="Ram is handling - no action","No action needed",IF(M7="","CALL 1: ring candidate, offer to book on call (Playbook C1)",IF(OR(M7="Scheduled on call",M7="Booked on their behalf"),"DONE: scheduled on call",IF(M7="Not interested/Declined","CLOSED: candidate declined (log + tell lead)",IF(N7="","CALL 2: final attempt (Playbook C2)",IF(OR(N7="Scheduled on call",N7="Booked on their behalf"),"DONE: scheduled on call",IF(N7="Escalate to AM","ESCALATED TO LEAD","Review"))))))) | G7: =IF(E7="Ram is handling - no action","",IF(M7="",B7+6/24,IF(AND(M7<>"Scheduled on call",M7<>"Booked on their behalf",M7<>"Not interested/Declined",N7=""),B7+20/24,""))) | H7: Chetan | I7: Google | J7: Round1 | K7: +91 9920264452 | L7: <calendly_link> | O7: =IF(OR(M7="Scheduled on call",M7="Booked on their behalf",N7="Scheduled on call",N7="Booked on their behalf"),"SCHEDULED (call)",IF(OR(M7="Not interested/Declined",N7="Not interested/Declined"),"DECLINED",IF(N7="Escalate to AM","ESCALATED TO LEAD",IF(E7="Ram is handling - no action","N/A",IF(M7="","PENDING CALL 1","IN PROGRESS"))))) | P7: =IF(OR('Ram - Digital ToDo'!O7="Scheduled",'Ram - Digital ToDo'!Q7="Scheduled"),"Scheduled within SLA (self-serve)",IF(OR(M7="Scheduled on call",M7="Booked on their behalf",N7="Scheduled on call",N7="Booked on their behalf"),"Scheduled within SLA (call)",IF(OR(M7="Not interested/Declined",N7="Not interested/Declined"),"Declined",IF(N7="Escalate to AM","SLA breach - unresolved","In progress"))))
A8: REQ-0007 | B8: 44867.799 | C8: =B8+1 | D8: =(C8-NOW())*24 | E8: =IF('Ram - Digital ToDo'!Q8="Escalate to call","CALL NOW",IF('Ram - Digital ToDo'!N8="Bad contact","CALL NOW (digital failed)","Ram is handling - no action")) | F8: =IF(E8="Ram is handling - no action","No action needed",IF(M8="","CALL 1: ring candidate, offer to book on call (Playbook C1)",IF(OR(M8="Scheduled on call",M8="Booked on their behalf"),"DONE: scheduled on call",IF(M8="Not interested/Declined","CLOSED: candidate declined (log + tell lead)",IF(N8="","CALL 2: final attempt (Playbook C2)",IF(OR(N8="Scheduled on call",N8="Booked on their behalf"),"DONE: scheduled on call",IF(N8="Escalate to AM","ESCALATED TO LEAD","Review"))))))) | G8: =IF(E8="Ram is handling - no action","",IF(M8="",B8+6/24,IF(AND(M8<>"Scheduled on call",M8<>"Booked on their behalf",M8<>"Not interested/Declined",N8=""),B8+20/24,""))) | H8: Chetan | I8: FB | J8: Round2 | K8: +91 9920264452 | L8: <calendly_link> | O8: =IF(OR(M8="Scheduled on call",M8="Booked on their behalf",N8="Scheduled on call",N8="Booked on their behalf"),"SCHEDULED (call)",IF(OR(M8="Not interested/Declined",N8="Not interested/Declined"),"DECLINED",IF(N8="Escalate to AM","ESCALATED TO LEAD",IF(E8="Ram is handling - no action","N/A",IF(M8="","PENDING CALL 1","IN PROGRESS"))))) | P8: =IF(OR('Ram - Digital ToDo'!O8="Scheduled",'Ram - Digital ToDo'!Q8="Scheduled"),"Scheduled within SLA (self-serve)",IF(OR(M8="Scheduled on call",M8="Booked on their behalf",N8="Scheduled on call",N8="Booked on their behalf"),"Scheduled within SLA (call)",IF(OR(M8="Not interested/Declined",N8="Not interested/Declined"),"Declined",IF(N8="Escalate to AM","SLA breach - unresolved","In progress"))))
A9: REQ-0008 | B9: 44867.806 | C9: =B9+1 | D9: =(C9-NOW())*24 | E9: =IF('Ram - Digital ToDo'!Q9="Escalate to call","CALL NOW",IF('Ram - Digital ToDo'!N9="Bad contact","CALL NOW (digital failed)","Ram is handling - no action")) | F9: =IF(E9="Ram is handling - no action","No action needed",IF(M9="","CALL 1: ring candidate, offer to book on call (Playbook C1)",IF(OR(M9="Scheduled on call",M9="Booked on their behalf"),"DONE: scheduled on call",IF(M9="Not interested/Declined","CLOSED: candidate declined (log + tell lead)",IF(N9="","CALL 2: final attempt (Playbook C2)",IF(OR(N9="Scheduled on call",N9="Booked on their behalf"),"DONE: scheduled on call",IF(N9="Escalate to AM","ESCALATED TO LEAD","Review"))))))) | G9: =IF(E9="Ram is handling - no action","",IF(M9="",B9+6/24,IF(AND(M9<>"Scheduled on call",M9<>"Booked on their behalf",M9<>"Not interested/Declined",N9=""),B9+20/24,""))) | H9: Chetan | I9: FB | J9: Round1 | K9: +91 9920264452 | L9: <calendly_link> | O9: =IF(OR(M9="Scheduled on call",M9="Booked on their behalf",N9="Scheduled on call",N9="Booked on their behalf"),"SCHEDULED (call)",IF(OR(M9="Not interested/Declined",N9="Not interested/Declined"),"DECLINED",IF(N9="Escalate to AM","ESCALATED TO LEAD",IF(E9="Ram is handling - no action","N/A",IF(M9="","PENDING CALL 1","IN PROGRESS"))))) | P9: =IF(OR('Ram - Digital ToDo'!O9="Scheduled",'Ram - Digital ToDo'!Q9="Scheduled"),"Scheduled within SLA (self-serve)",IF(OR(M9="Scheduled on call",M9="Booked on their behalf",N9="Scheduled on call",N9="Booked on their behalf"),"Scheduled within SLA (call)",IF(OR(M9="Not interested/Declined",N9="Not interested/Declined"),"Declined",IF(N9="Escalate to AM","SLA breach - unresolved","In progress"))))
A10: REQ-0009 | B10: 44867.827 | C10: =B10+1 | D10: =(C10-NOW())*24 | E10: =IF('Ram - Digital ToDo'!Q10="Escalate to call","CALL NOW",IF('Ram - Digital ToDo'!N10="Bad contact","CALL NOW (digital failed)","Ram is handling - no action")) | F10: =IF(E10="Ram is handling - no action","No action needed",IF(M10="","CALL 1: ring candidate, offer to book on call (Playbook C1)",IF(OR(M10="Scheduled on call",M10="Booked on their behalf"),"DONE: scheduled on call",IF(M10="Not interested/Declined","CLOSED: candidate declined (log + tell lead)",IF(N10="","CALL 2: final attempt (Playbook C2)",IF(OR(N10="Scheduled on call",N10="Booked on their behalf"),"DONE: scheduled on call",IF(N10="Escalate to AM","ESCALATED TO LEAD","Review"))))))) | G10: =IF(E10="Ram is handling - no action","",IF(M10="",B10+6/24,IF(AND(M10<>"Scheduled on call",M10<>"Booked on their behalf",M10<>"Not interested/Declined",N10=""),B10+20/24,""))) | H10: Chetan | I10: Google | J10: Round1 | K10: +91 9920264452 | L10: <calendly_link> | O10: =IF(OR(M10="Scheduled on call",M10="Booked on their behalf",N10="Scheduled on call",N10="Booked on their behalf"),"SCHEDULED (call)",IF(OR(M10="Not interested/Declined",N10="Not interested/Declined"),"DECLINED",IF(N10="Escalate to AM","ESCALATED TO LEAD",IF(E10="Ram is handling - no action","N/A",IF(M10="","PENDING CALL 1","IN PROGRESS"))))) | P10: =IF(OR('Ram - Digital ToDo'!O10="Scheduled",'Ram - Digital ToDo'!Q10="Scheduled"),"Scheduled within SLA (self-serve)",IF(OR(M10="Scheduled on call",M10="Booked on their behalf",N10="Scheduled on call",N10="Booked on their behalf"),"Scheduled within SLA (call)",IF(OR(M10="Not interested/Declined",N10="Not interested/Declined"),"Declined",IF(N10="Escalate to AM","SLA breach - unresolved","In progress"))))
A11: REQ-0010 | B11: 44867.827 | C11: =B11+1 | D11: =(C11-NOW())*24 | E11: =IF('Ram - Digital ToDo'!Q11="Escalate to call","CALL NOW",IF('Ram - Digital ToDo'!N11="Bad contact","CALL NOW (digital failed)","Ram is handling - no action")) | F11: =IF(E11="Ram is handling - no action","No action needed",IF(M11="","CALL 1: ring candidate, offer to book on call (Playbook C1)",IF(OR(M11="Scheduled on call",M11="Booked on their behalf"),"DONE: scheduled on call",IF(M11="Not interested/Declined","CLOSED: candidate declined (log + tell lead)",IF(N11="","CALL 2: final attempt (Playbook C2)",IF(OR(N11="Scheduled on call",N11="Booked on their behalf"),"DONE: scheduled on call",IF(N11="Escalate to AM","ESCALATED TO LEAD","Review"))))))) | G11: =IF(E11="Ram is handling - no action","",IF(M11="",B11+6/24,IF(AND(M11<>"Scheduled on call",M11<>"Booked on their behalf",M11<>"Not interested/Declined",N11=""),B11+20/24,""))) | H11: Chetan | I11: FB | J11: Round2 | K11: +91 9920264452 | L11: <calendly_link> | O11: =IF(OR(M11="Scheduled on call",M11="Booked on their behalf",N11="Scheduled on call",N11="Booked on their behalf"),"SCHEDULED (call)",IF(OR(M11="Not interested/Declined",N11="Not interested/Declined"),"DECLINED",IF(N11="Escalate to AM","ESCALATED TO LEAD",IF(E11="Ram is handling - no action","N/A",IF(M11="","PENDING CALL 1","IN PROGRESS"))))) | P11: =IF(OR('Ram - Digital ToDo'!O11="Scheduled",'Ram - Digital ToDo'!Q11="Scheduled"),"Scheduled within SLA (self-serve)",IF(OR(M11="Scheduled on call",M11="Booked on their behalf",N11="Scheduled on call",N11="Booked on their behalf"),"Scheduled within SLA (call)",IF(OR(M11="Not interested/Declined",N11="Not interested/Declined"),"Declined",IF(N11="Escalate to AM","SLA breach - unresolved","In progress"))))
A12: REQ-0011 | B12: 44867.827 | C12: =B12+1 | D12: =(C12-NOW())*24 | E12: =IF('Ram - Digital ToDo'!Q12="Escalate to call","CALL NOW",IF('Ram - Digital ToDo'!N12="Bad contact","CALL NOW (digital failed)","Ram is handling - no action")) | F12: =IF(E12="Ram is handling - no action","No action needed",IF(M12="","CALL 1: ring candidate, offer to book on call (Playbook C1)",IF(OR(M12="Scheduled on call",M12="Booked on their behalf"),"DONE: scheduled on call",IF(M12="Not interested/Declined","CLOSED: candidate declined (log + tell lead)",IF(N12="","CALL 2: final attempt (Playbook C2)",IF(OR(N12="Scheduled on call",N12="Booked on their behalf"),"DONE: scheduled on call",IF(N12="Escalate to AM","ESCALATED TO LEAD","Review"))))))) | G12: =IF(E12="Ram is handling - no action","",IF(M12="",B12+6/24,IF(AND(M12<>"Scheduled on call",M12<>"Booked on their behalf",M12<>"Not interested/Declined",N12=""),B12+20/24,""))) | H12: Chetan | I12: Tesla | J12: Round1 | K12: +91 9920264452 | L12: <calendly_link> | O12: =IF(OR(M12="Scheduled on call",M12="Booked on their behalf",N12="Scheduled on call",N12="Booked on their behalf"),"SCHEDULED (call)",IF(OR(M12="Not interested/Declined",N12="Not interested/Declined"),"DECLINED",IF(N12="Escalate to AM","ESCALATED TO LEAD",IF(E12="Ram is handling - no action","N/A",IF(M12="","PENDING CALL 1","IN PROGRESS"))))) | P12: =IF(OR('Ram - Digital ToDo'!O12="Scheduled",'Ram - Digital ToDo'!Q12="Scheduled"),"Scheduled within SLA (self-serve)",IF(OR(M12="Scheduled on call",M12="Booked on their behalf",N12="Scheduled on call",N12="Booked on their behalf"),"Scheduled within SLA (call)",IF(OR(M12="Not interested/Declined",N12="Not interested/Declined"),"Declined",IF(N12="Escalate to AM","SLA breach - unresolved","In progress"))))
